gyp info it worked if it ends with ok
gyp info using node-gyp@9.3.0
gyp info using node@18.12.1 | linux | x64
gyp info find Python using Python version 3.11.1 found at "/usr/local/bin/python3"
gyp info spawn /usr/local/bin/python3
gyp info spawn args [
gyp info spawn args   '/usr/share/nodejs/node-gyp/gyp/gyp_main.py',
gyp info spawn args   'binding.gyp',
gyp info spawn args   '-f',
gyp info spawn args   'make',
gyp info spawn args   '-I',
gyp info spawn args   '/home/mrdefacer404/Desktop/File/discordbot/node_modules/@discordjs/uws/build/config.gypi',
gyp info spawn args   '-I',
gyp info spawn args   '/usr/share/nodejs/node-gyp/addon.gypi',
gyp info spawn args   '-I',
gyp info spawn args   '/usr/include/nodejs/common.gypi',
gyp info spawn args   '-Dlibrary=shared_library',
gyp info spawn args   '-Dvisibility=default',
gyp info spawn args   '-Dnode_root_dir=/usr/include/nodejs',
gyp info spawn args   '-Dnode_gyp_dir=/usr/share/nodejs/node-gyp',
gyp info spawn args   '-Dnode_lib_file=/usr/include/nodejs/<(target_arch)/node.lib',
gyp info spawn args   '-Dmodule_root_dir=/home/mrdefacer404/Desktop/File/discordbot/node_modules/@discordjs/uws',
gyp info spawn args   '-Dnode_engine=v8',
gyp info spawn args   '--depth=.',
gyp info spawn args   '--no-parallel',
gyp info spawn args   '--generator-output',
gyp info spawn args   'build',
gyp info spawn args   '-Goutput_dir=.'
gyp info spawn args ]
Traceback (most recent call last):
  File "/usr/local/lib/python3.11/importlib/metadata/__init__.py", line 563, in from_name
    return next(cls.discover(name=name))
           ^^^^^^^^^^^^^^^^^^^^^^^^^^^^^
StopIteration

During handling of the above exception, another exception occurred:

Traceback (most recent call last):
  File "/usr/share/nodejs/node-gyp/gyp/gyp_main.py", line 33, in <module>
    sys.exit(load_entry_point('gyp==0.1', 'console_scripts', 'gyp')())
             ^^^^^^^^^^^^^^^^^^^^^^^^^^^^^^^^^^^^^^^^^^^^^^^^^^^^^^
  File "/usr/share/nodejs/node-gyp/gyp/gyp_main.py", line 22, in importlib_load_entry_point
    for entry_point in distribution(dist_name).entry_points
                       ^^^^^^^^^^^^^^^^^^^^^^^
  File "/usr/local/lib/python3.11/importlib/metadata/__init__.py", line 981, in distribution
    return Distribution.from_name(distribution_name)
           ^^^^^^^^^^^^^^^^^^^^^^^^^^^^^^^^^^^^^^^^^
  File "/usr/local/lib/python3.11/importlib/metadata/__init__.py", line 565, in from_name
    raise PackageNotFoundError(name)
importlib.metadata.PackageNotFoundError: No package metadata was found for gyp
gyp ERR! configure error 
gyp ERR! stack Error: `gyp` failed with exit code: 1
gyp ERR! stack     at ChildProcess.onCpExit (/usr/share/nodejs/node-gyp/lib/configure.js:329:16)
gyp ERR! stack     at ChildProcess.emit (node:events:513:28)
gyp ERR! stack     at ChildProcess._handle.onexit (node:internal/child_process:291:12)
gyp ERR! System Linux 6.0.0-kali3-amd64
gyp ERR! command "/usr/bin/node" "/usr/share/nodejs/node-gyp/bin/node-gyp.js" "rebuild"
gyp ERR! cwd /home/mrdefacer404/Desktop/File/discordbot/node_modules/@discordjs/uws
gyp ERR! node -v v18.12.1
gyp ERR! node-gyp -v v9.3.0
gyp ERR! not ok 
